<!-- 需求：设置机器人底盘，并添加摄像头 -->
<robot name="mycar">
    <!-- 1.底盘link -->
    <link name="base_link">
        <visual>
            <geometry>
                <box size="0.3 0.2 0.1"/>
            </geometry>
            <origin xyz="0.0 0.0 0.0" rpy="0.0 0.0 0.0"/>
            <material name="car_color">
                <color rgba="0.8 0.4 0.0 0.5"/>
            </material>
        </visual>
        
    </link>
    <!-- 2.摄像头link -->
        <link name="camera">
        <visual>
            <geometry>
                <box size="0.02 0.05 0.05"/>
            </geometry>
            <!-- 默认情况下关节点的和连杆的中心点重叠， camera的中心需要往上移动半个camera的高度 -->
            <origin xyz="0.0 0.0 0.025" rpy="0.0 0.0 0.0"/>
            <material name="car_color">
                <color rgba="0 0.8 0.4 0.5"/>
            </material>
        </visual>
        
    </link>

    <!-- 3.关节 -->
    <joint name="camera2base" type="continuous">
        <!-- 父级link -->
        <parent link="base_link"/>
        
        <!-- 子级link -->
        <child link="camera"/>

        <!-- 设置偏移量 -->
        <origin xyz="0.12 0.00 0.05" rpy="0.0 0.0 0.0"/>
        <!-- 关节绕着什么轴旋转 -->
        <axis xyz="0 0 1" />
        
    </joint>

    
</robot>